<?xml version="1.0" encoding="utf-8"?>
<!-- =================================================================================== -->
<!-- |    This document was autogenerated by xacro from senhance_or.urdf.xacro         | -->
<!-- |    EDITING THIS FILE BY HAND IS NOT RECOMMENDED                                 | -->
<!-- =================================================================================== -->
<robot name="senhance_or" xmlns:xacro="http://ros.org/wiki/xacro">
  <material name="Black">
    <color rgba="0.0 0.0 0.0 1.0"/>
  </material>
  <material name="Blue">
    <color rgba="0.0 0.5 1.0 1.0"/>
  </material>
  <material name="Green">
    <color rgba="0.0 0.8 0.0 1.0"/>
  </material>
  <material name="Grey">
    <color rgba="0.4 0.4 0.4 1.0"/>
  </material>
  <material name="Orange">
    <color rgba="1.0 0.423529411765 0.0392156862745 1.0"/>
  </material>
  <material name="Brown">
    <color rgba="0.870588235294 0.811764705882 0.764705882353 1.0"/>
  </material>
  <material name="Red">
    <color rgba="0.8 0.0 0.0 1.0"/>
  </material>
  <material name="White">
    <color rgba="1.0 1.0 1.0 1.0"/>
  </material>
  <link name="link_world"/>
  <!-- Links -->
  <link name="robot1_link_cart">
    <visual>
      <origin rpy="0 0 0" xyz="0 0 0"/>
      <geometry>
        <mesh filename="package://trx_arm_description/meshes/senhance/Base_part.STL"/>
      </geometry>
      <material name="Blue"/>
    </visual>
    <collision>
      <origin rpy="0 0 0" xyz="0 0 0"/>
      <geometry>
        <mesh filename="package://trx_arm_description/meshes/senhance/Base_part.STL"/>
      </geometry>
    </collision>
  </link>
  <link name="robot1_link_1">
    <visual>
      <origin rpy="0 0 0" xyz="0 0 0"/>
      <geometry>
        <mesh filename="package://trx_arm_description/meshes/senhance/J1_part.STL"/>
      </geometry>
      <material name="Blue"/>
    </visual>
    <collision>
      <origin rpy="0 0 0" xyz="0 0 0"/>
      <geometry>
        <mesh filename="package://trx_arm_description/meshes/senhance/J1_part.STL"/>
      </geometry>
    </collision>
  </link>
  <link name="robot1_link_2">
    <visual>
      <origin rpy="0 0 0" xyz="0 0 0"/>
      <geometry>
        <mesh filename="package://trx_arm_description/meshes/senhance/J2_part.STL"/>
      </geometry>
      <material name="Blue"/>
    </visual>
    <collision>
      <origin rpy="0 0 0" xyz="0 0 0"/>
      <geometry>
        <mesh filename="package://trx_arm_description/meshes/senhance/J2_part.STL"/>
      </geometry>
    </collision>
  </link>
  <link name="robot1_link_3">
    <visual>
      <origin rpy="0 0 0" xyz="0 0 0"/>
      <geometry>
        <mesh filename="package://trx_arm_description/meshes/senhance/J3_part.STL"/>
      </geometry>
      <material name="Blue"/>
    </visual>
    <collision>
      <origin rpy="0 0 0" xyz="0 0 0"/>
      <geometry>
        <mesh filename="package://trx_arm_description/meshes/senhance/J3_part.STL"/>
      </geometry>
    </collision>
  </link>
  <link name="robot1_link_4">
    <visual>
      <origin rpy="0 0 0" xyz="0 0 0"/>
      <geometry>
        <mesh filename="package://trx_arm_description/meshes/senhance/J4_part.STL"/>
      </geometry>
      <material name="Blue"/>
    </visual>
    <collision>
      <origin rpy="0 0 0" xyz="0 0 0"/>
      <geometry>
        <mesh filename="package://trx_arm_description/meshes/senhance/J4_part.STL"/>
      </geometry>
    </collision>
  </link>
  <link name="robot1_link_5">
    <visual>
      <origin rpy="0 0 0" xyz="0 0 0"/>
      <geometry>
        <mesh filename="package://trx_arm_description/meshes/senhance/J5_part.STL"/>
      </geometry>
      <material name="Blue"/>
    </visual>
    <collision>
      <origin rpy="0 0 0" xyz="0 0 0"/>
      <geometry>
        <mesh filename="package://trx_arm_description/meshes/senhance/J5_part.STL"/>
      </geometry>
    </collision>
  </link>
  <link name="robot1_link_6">
    <visual>
      <origin rpy="0 0 0" xyz="0 0 0"/>
      <geometry>
        <mesh filename="package://trx_arm_description/meshes/senhance/J6_part.STL"/>
      </geometry>
      <material name="Blue"/>
    </visual>
    <collision>
      <origin rpy="0 0 0" xyz="0 0 0"/>
      <geometry>
        <mesh filename="package://trx_arm_description/meshes/senhance/J6_part.STL"/>
      </geometry>
    </collision>
  </link>
  <link name="robot1_link_instrument">
    <visual>
      <origin rpy="0 0 0" xyz="0 0 0"/>
      <geometry>
        <mesh filename="package://trx_arm_description/meshes/senhance/Instrument_part.STL"/>
      </geometry>
      <material name="Blue"/>
    </visual>
    <collision>
      <origin rpy="0 0 0" xyz="0 0 0"/>
      <geometry>
        <mesh filename="package://trx_arm_description/meshes/senhance/Instrument_part.STL"/>
      </geometry>
    </collision>
  </link>
  <link name="robot1_link_end_effector">
		</link>
  <!-- Joints -->
  <joint name="robot1_joint1" type="prismatic">
    <parent link="robot1_link_cart"/>
    <child link="robot1_link_1"/>
    <origin rpy="0 0 0" xyz="0 0 0"/>
    <axis xyz="0 0 1"/>
    <limit effort="100" lower="0.0" upper="0.57" velocity="100"/>
  </joint>
  <joint name="robot1_joint2" type="revolute">
    <parent link="robot1_link_1"/>
    <child link="robot1_link_2"/>
    <origin rpy="0 0 0" xyz="0 0 1.29"/>
    <axis xyz="0 0 1"/>
    <limit effort="100" lower="-1.57079632679" upper="1.57079632679" velocity="100"/>
  </joint>
  <joint name="robot1_joint3" type="prismatic">
    <parent link="robot1_link_2"/>
    <child link="robot1_link_3"/>
    <origin rpy="0 0 0" xyz="0 0 0"/>
    <axis xyz="1 0 0"/>
    <limit effort="100" lower="0.0" upper="0.74" velocity="100"/>
  </joint>
  <joint name="robot1_joint4" type="continuous">
    <parent link="robot1_link_3"/>
    <child link="robot1_link_4"/>
    <origin rpy="0 0 0" xyz="0.835 0 -0.02"/>
    <axis xyz="0 0 1"/>
    <limit effort="100" velocity="100"/>
  </joint>
  <joint name="robot1_joint5" type="revolute">
    <parent link="robot1_link_4"/>
    <child link="robot1_link_5"/>
    <origin rpy="0 0 0" xyz="0 0 -0.281"/>
    <axis xyz="1 0 0"/>
    <limit effort="100" lower="-1.57079632679" upper="1.57079632679" velocity="100"/>
  </joint>
  <joint name="robot1_joint6" type="continuous">
    <parent link="robot1_link_5"/>
    <child link="robot1_link_6"/>
    <origin rpy="0 0 0" xyz="0.091 0 -0.01"/>
    <axis xyz="0 0 1"/>
    <limit effort="100" velocity="100"/>
  </joint>
  <joint name="robot1_tool_adaptor" type="fixed">
    <parent link="robot1_link_6"/>
    <child link="robot1_link_instrument"/>
    <origin rpy="0 0 0" xyz="0 0 -0.21"/>
  </joint>
  <joint name="robot1_link_end_effector_offset" type="fixed">
    <parent link="robot1_link_instrument"/>
    <child link="robot1_link_end_effector"/>
    <origin rpy="3.14159265359 0 0" xyz="0 0 -0.3052"/>
  </joint>
  <joint name="joint_world_robot1" type="fixed">
    <origin rpy="0 0 0" xyz="0 0 0"/>
    <parent link="link_world"/>
    <child link="robot1_link_cart"/>
  </joint>
</robot>

